2024-11-29 06:54:43.789 Uncaught app exception
Traceback (most recent call last):
  File "/home/codespace/.local/lib/python3.12/site-packages/pandas/core/indexes/base.py", line 3805, in get_loc
    return self._engine.get_loc(casted_key)
           ^^^^^^^^^^^^^^^^^^^^^^^^^^^^^^^^
  File "index.pyx", line 167, in pandas._libs.index.IndexEngine.get_loc
  File "index.pyx", line 196, in pandas._libs.index.IndexEngine.get_loc
  File "pandas/_libs/hashtable_class_helper.pxi", line 7081, in pandas._libs.hashtable.PyObjectHashTable.get_item
  File "pandas/_libs/hashtable_class_helper.pxi", line 7089, in pandas._libs.hashtable.PyObjectHashTable.get_item
KeyError: 'rule_id'

The above exception was the direct cause of the following exception:

Traceback (most recent call last):
  File "/usr/local/python/3.12.1/lib/python3.12/site-packages/streamlit/runtime/scriptrunner/exec_code.py", line 88, in exec_func_with_error_handling
    result = func()
             ^^^^^^
  File "/usr/local/python/3.12.1/lib/python3.12/site-packages/streamlit/runtime/scriptrunner/script_runner.py", line 579, in code_to_exec
    exec(code, module.__dict__)
  File "/workspaces/Network-Traffic-Analyser/firewall.py", line 51, in <module>
    rules = [FirewallRule(row['rule_id'], row['protocol'], row['src_ip'], row['dest_ip'], row['src_port'], row['dest_port'], row['action']) for index, row in df.iterrows()]
                          ~~~^^^^^^^^^^^
  File "/home/codespace/.local/lib/python3.12/site-packages/pandas/core/series.py", line 1121, in __getitem__
    return self._get_value(key)
           ^^^^^^^^^^^^^^^^^^^^
  File "/home/codespace/.local/lib/python3.12/site-packages/pandas/core/series.py", line 1237, in _get_value
    loc = self.index.get_loc(label)
          ^^^^^^^^^^^^^^^^^^^^^^^^^
  File "/home/codespace/.local/lib/python3.12/site-packages/pandas/core/indexes/base.py", line 3812, in get_loc
    raise KeyError(key) from err
KeyError: 'rule_id'
